2021-12-31 15:11:07,673 INFO    MainThread:89942 [wandb_setup.py:_flush():69] setting env: {'entity': 'rishanthrajendhran', 'project': 'eigengame', 'sweep_id': '0b7poduc', 'root_dir': '/Users/rishanthrajendhran/Desktop/EigenGame', 'run_id': 'yhwg5ffg', 'sweep_param_path': '/Users/rishanthrajendhran/Desktop/EigenGame/wandb/sweep-0b7poduc/config-yhwg5ffg.yaml'}
2021-12-31 15:11:07,674 INFO    MainThread:89942 [wandb_setup.py:_flush():69] setting login settings: {}
2021-12-31 15:11:07,674 INFO    MainThread:89942 [wandb_init.py:_log_setup():357] Logging user logs to /Users/rishanthrajendhran/Desktop/EigenGame/wandb/run-20211231_151107-yhwg5ffg/logs/debug.log
2021-12-31 15:11:07,674 INFO    MainThread:89942 [wandb_init.py:_log_setup():358] Logging internal logs to /Users/rishanthrajendhran/Desktop/EigenGame/wandb/run-20211231_151107-yhwg5ffg/logs/debug-internal.log
2021-12-31 15:11:07,674 INFO    MainThread:89942 [wandb_init.py:init():390] calling init triggers
2021-12-31 15:11:07,674 INFO    MainThread:89942 [wandb_init.py:init():397] wandb.init called with sweep_config: {'learningRate': 45, 'numStepsPerIteration': 200}
config: {'xDim': (10000, 7), 'numIterations': 35000, 'numStepsPerIteration': 100, 'k': 7, 'learningRate': 1, 'flags': ['-rmsprop'], 'isSymmetric': False, 'variant': 'a', 'tolerance': 10, 'distanceTolerance': 0.01}
2021-12-31 15:11:07,674 INFO    MainThread:89942 [wandb_init.py:init():435] starting backend
2021-12-31 15:11:07,675 INFO    MainThread:89942 [backend.py:_multiprocessing_setup():72] multiprocessing start_methods=fork,spawn,forkserver, using: spawn
2021-12-31 15:11:07,697 INFO    MainThread:89942 [backend.py:ensure_launched():135] starting backend process...
2021-12-31 15:11:07,705 INFO    MainThread:89942 [backend.py:ensure_launched():140] started backend process with pid: 89965
2021-12-31 15:11:07,709 INFO    MainThread:89942 [wandb_init.py:init():440] backend started and connected
2021-12-31 15:11:07,711 INFO    MainThread:89942 [wandb_run.py:_config_callback():878] config_cb None None {'learningRate': 45, 'numStepsPerIteration': 200}
2021-12-31 15:11:07,712 INFO    MainThread:89942 [wandb_init.py:init():499] updated telemetry
2021-12-31 15:11:07,712 INFO    MainThread:89942 [wandb_init.py:init():522] communicating current version
2021-12-31 15:11:12,633 INFO    MainThread:89942 [wandb_init.py:init():527] got version response 
2021-12-31 15:11:12,633 INFO    MainThread:89942 [wandb_init.py:init():535] communicating run to backend with 30 second timeout
2021-12-31 15:11:17,033 ERROR   Thread-1  :89942 [retry.py:__call__():126] Retry attempt failed:
Traceback (most recent call last):
  File "/Users/rishanthrajendhran/opt/anaconda3/lib/python3.7/site-packages/urllib3/connection.py", line 170, in _new_conn
    (self._dns_host, self.port), self.timeout, **extra_kw
  File "/Users/rishanthrajendhran/opt/anaconda3/lib/python3.7/site-packages/urllib3/util/connection.py", line 73, in create_connection
    for res in socket.getaddrinfo(host, port, family, socket.SOCK_STREAM):
  File "/Users/rishanthrajendhran/opt/anaconda3/lib/python3.7/socket.py", line 748, in getaddrinfo
    for res in _socket.getaddrinfo(host, port, family, type, proto, flags):
socket.gaierror: [Errno 8] nodename nor servname provided, or not known

During handling of the above exception, another exception occurred:

Traceback (most recent call last):
  File "/Users/rishanthrajendhran/opt/anaconda3/lib/python3.7/site-packages/urllib3/connectionpool.py", line 706, in urlopen
    chunked=chunked,
  File "/Users/rishanthrajendhran/opt/anaconda3/lib/python3.7/site-packages/urllib3/connectionpool.py", line 382, in _make_request
    self._validate_conn(conn)
  File "/Users/rishanthrajendhran/opt/anaconda3/lib/python3.7/site-packages/urllib3/connectionpool.py", line 1010, in _validate_conn
    conn.connect()
  File "/Users/rishanthrajendhran/opt/anaconda3/lib/python3.7/site-packages/urllib3/connection.py", line 353, in connect
    conn = self._new_conn()
  File "/Users/rishanthrajendhran/opt/anaconda3/lib/python3.7/site-packages/urllib3/connection.py", line 182, in _new_conn
    self, "Failed to establish a new connection: %s" % e
urllib3.exceptions.NewConnectionError: <urllib3.connection.HTTPSConnection object at 0x7ff3de6ea150>: Failed to establish a new connection: [Errno 8] nodename nor servname provided, or not known

During handling of the above exception, another exception occurred:

Traceback (most recent call last):
  File "/Users/rishanthrajendhran/opt/anaconda3/lib/python3.7/site-packages/requests/adapters.py", line 449, in send
    timeout=timeout
  File "/Users/rishanthrajendhran/opt/anaconda3/lib/python3.7/site-packages/urllib3/connectionpool.py", line 756, in urlopen
    method, url, error=e, _pool=self, _stacktrace=sys.exc_info()[2]
  File "/Users/rishanthrajendhran/opt/anaconda3/lib/python3.7/site-packages/urllib3/util/retry.py", line 573, in increment
    raise MaxRetryError(_pool, url, error or ResponseError(cause))
urllib3.exceptions.MaxRetryError: HTTPSConnectionPool(host='api.wandb.ai', port=443): Max retries exceeded with url: /graphql (Caused by NewConnectionError('<urllib3.connection.HTTPSConnection object at 0x7ff3de6ea150>: Failed to establish a new connection: [Errno 8] nodename nor servname provided, or not known'))

During handling of the above exception, another exception occurred:

Traceback (most recent call last):
  File "/Users/rishanthrajendhran/opt/anaconda3/lib/python3.7/site-packages/wandb/sdk/lib/retry.py", line 102, in __call__
    result = self._call_fn(*args, **kwargs)
  File "/Users/rishanthrajendhran/opt/anaconda3/lib/python3.7/site-packages/wandb/sdk/internal/internal_api.py", line 132, in execute
    return self.client.execute(*args, **kwargs)
  File "/Users/rishanthrajendhran/opt/anaconda3/lib/python3.7/site-packages/wandb/vendor/gql-0.2.0/gql/client.py", line 52, in execute
    result = self._get_result(document, *args, **kwargs)
  File "/Users/rishanthrajendhran/opt/anaconda3/lib/python3.7/site-packages/wandb/vendor/gql-0.2.0/gql/client.py", line 60, in _get_result
    return self.transport.execute(document, *args, **kwargs)
  File "/Users/rishanthrajendhran/opt/anaconda3/lib/python3.7/site-packages/wandb/vendor/gql-0.2.0/gql/transport/requests.py", line 38, in execute
    request = requests.post(self.url, **post_args)
  File "/Users/rishanthrajendhran/opt/anaconda3/lib/python3.7/site-packages/requests/api.py", line 119, in post
    return request('post', url, data=data, json=json, **kwargs)
  File "/Users/rishanthrajendhran/opt/anaconda3/lib/python3.7/site-packages/requests/api.py", line 61, in request
    return session.request(method=method, url=url, **kwargs)
  File "/Users/rishanthrajendhran/opt/anaconda3/lib/python3.7/site-packages/requests/sessions.py", line 542, in request
    resp = self.send(prep, **send_kwargs)
  File "/Users/rishanthrajendhran/opt/anaconda3/lib/python3.7/site-packages/requests/sessions.py", line 655, in send
    r = adapter.send(request, **kwargs)
  File "/Users/rishanthrajendhran/opt/anaconda3/lib/python3.7/site-packages/requests/adapters.py", line 516, in send
    raise ConnectionError(e, request=request)
requests.exceptions.ConnectionError: HTTPSConnectionPool(host='api.wandb.ai', port=443): Max retries exceeded with url: /graphql (Caused by NewConnectionError('<urllib3.connection.HTTPSConnection object at 0x7ff3de6ea150>: Failed to establish a new connection: [Errno 8] nodename nor servname provided, or not known'))
2021-12-31 15:11:24,431 INFO    MainThread:89942 [wandb_init.py:init():562] starting run threads in backend
2021-12-31 15:11:29,440 INFO    MainThread:89942 [wandb_run.py:_console_start():1651] atexit reg
2021-12-31 15:11:29,441 INFO    MainThread:89942 [wandb_run.py:_redirect():1525] redirect: SettingsConsole.REDIRECT
2021-12-31 15:11:29,442 INFO    MainThread:89942 [wandb_run.py:_redirect():1530] Redirecting console.
2021-12-31 15:11:29,443 INFO    MainThread:89942 [wandb_run.py:_redirect():1586] Redirects installed.
2021-12-31 15:11:29,443 INFO    MainThread:89942 [wandb_init.py:init():587] run started, returning control to user process
2021-12-31 15:14:31,567 INFO    MainThread:89942 [wandb_run.py:finish():1311] finishing run rishanthrajendhran/eigengame/yhwg5ffg
2021-12-31 15:14:31,568 INFO    MainThread:89942 [wandb_run.py:_atexit_cleanup():1621] got exitcode: 0
2021-12-31 15:14:31,570 INFO    MainThread:89942 [wandb_run.py:_restore():1593] restore
2021-12-31 15:14:34,327 INFO    MainThread:89942 [wandb_run.py:_wait_for_finish():1746] got exit ret: file_counts {
  wandb_count: 1
}
pusher_stats {
  uploaded_bytes: 824
  total_bytes: 824
}

2021-12-31 15:14:34,730 INFO    MainThread:89942 [wandb_run.py:_wait_for_finish():1746] got exit ret: file_counts {
  wandb_count: 1
}
pusher_stats {
  uploaded_bytes: 824
  total_bytes: 824
}

2021-12-31 15:14:35,161 INFO    MainThread:89942 [wandb_run.py:_wait_for_finish():1746] got exit ret: file_counts {
  wandb_count: 6
}
pusher_stats {
  uploaded_bytes: 824
  total_bytes: 17590
}

2021-12-31 15:14:35,264 INFO    MainThread:89942 [wandb_run.py:_wait_for_finish():1746] got exit ret: file_counts {
  wandb_count: 6
}
pusher_stats {
  uploaded_bytes: 824
  total_bytes: 17590
}

2021-12-31 15:14:35,370 INFO    MainThread:89942 [wandb_run.py:_wait_for_finish():1746] got exit ret: file_counts {
  wandb_count: 6
}
pusher_stats {
  uploaded_bytes: 824
  total_bytes: 17590
}

2021-12-31 15:14:35,473 INFO    MainThread:89942 [wandb_run.py:_wait_for_finish():1746] got exit ret: file_counts {
  wandb_count: 6
}
pusher_stats {
  uploaded_bytes: 824
  total_bytes: 17590
}

2021-12-31 15:14:35,578 INFO    MainThread:89942 [wandb_run.py:_wait_for_finish():1746] got exit ret: file_counts {
  wandb_count: 6
}
pusher_stats {
  uploaded_bytes: 824
  total_bytes: 17590
}

2021-12-31 15:14:35,682 INFO    MainThread:89942 [wandb_run.py:_wait_for_finish():1746] got exit ret: file_counts {
  wandb_count: 6
}
pusher_stats {
  uploaded_bytes: 17590
  total_bytes: 17590
}

2021-12-31 15:14:35,790 INFO    MainThread:89942 [wandb_run.py:_wait_for_finish():1746] got exit ret: file_counts {
  wandb_count: 6
}
pusher_stats {
  uploaded_bytes: 17590
  total_bytes: 17590
}

2021-12-31 15:14:35,893 INFO    MainThread:89942 [wandb_run.py:_wait_for_finish():1746] got exit ret: file_counts {
  wandb_count: 6
}
pusher_stats {
  uploaded_bytes: 17590
  total_bytes: 17590
}

2021-12-31 15:14:35,997 INFO    MainThread:89942 [wandb_run.py:_wait_for_finish():1746] got exit ret: file_counts {
  wandb_count: 6
}
pusher_stats {
  uploaded_bytes: 17590
  total_bytes: 17590
}

2021-12-31 15:14:36,102 INFO    MainThread:89942 [wandb_run.py:_wait_for_finish():1746] got exit ret: file_counts {
  wandb_count: 6
}
pusher_stats {
  uploaded_bytes: 17590
  total_bytes: 17590
}

2021-12-31 15:14:36,206 INFO    MainThread:89942 [wandb_run.py:_wait_for_finish():1746] got exit ret: file_counts {
  wandb_count: 6
}
pusher_stats {
  uploaded_bytes: 17590
  total_bytes: 17590
}

2021-12-31 15:14:36,313 INFO    MainThread:89942 [wandb_run.py:_wait_for_finish():1746] got exit ret: file_counts {
  wandb_count: 6
}
pusher_stats {
  uploaded_bytes: 17590
  total_bytes: 17590
}

2021-12-31 15:14:36,974 INFO    MainThread:89942 [wandb_run.py:_wait_for_finish():1746] got exit ret: file_counts {
  wandb_count: 6
}
pusher_stats {
  uploaded_bytes: 17590
  total_bytes: 17590
}

2021-12-31 15:14:37,695 INFO    MainThread:89942 [wandb_run.py:_wait_for_finish():1746] got exit ret: done: true
exit_result {
}
file_counts {
  wandb_count: 6
}
pusher_stats {
  uploaded_bytes: 17590
  total_bytes: 17590
}
local_info {
}

2021-12-31 15:14:39,194 INFO    MainThread:89942 [wandb_run.py:_append_history():1959] rendering history
2021-12-31 15:14:39,194 INFO    MainThread:89942 [wandb_run.py:_append_summary():1914] rendering summary
2021-12-31 15:14:39,194 INFO    MainThread:89942 [wandb_run.py:_append_files():2009] logging synced files
